Workbook

Sheet How to use
A1: Cowork — task lifecycle test pack
A2: Creation to submission, same department and cross department, plus the home page's active-work bar against the Tasks surfaces.
A5: What this pack covers
A6: Scope | B6: One task's whole life: raising it, the approval gates, the assignee taking it on, the time-budget loop, the deadline and requests for more time, the clock, handing the work in, review, rework and completion — each tested inside one department and across two.
A7: Two E2E tabs | B7: “E2E same-dept” and “E2E cross-dept” are SCRIPTED RUNS: the rows go in order and each one assumes the row above passed. Everything else can be run in any order.
A8: Bar parity | B8: The “Bar parity” tab is the specific ask: the active-work bar on /home must offer the same step, in the same words, writing the same record, as the Tasks surfaces. Anything that differs is a defect on the bar, not a variation.
A10: Before you start
A11: Build under test | B11: Record the commit SHA here →
A12: Environment | B12: Record the URL / environment here →
A13: Tested by | B13: Record here →
A14: Start date | B14: Record here →
A15: Settings state | B15: Several Submission cases change the task rules in the settings console. Record the STARTING values here → and put them back afterwards.
A16: Task rules defaults | B16: Criteria before submit: Off. Timer before submit: Allow. Submission note: Optional. After rejection: Allow resubmit. An unsaved settings document means these defaults are in force.
A18: The org you need
A19: Fixtures tab | B19: The Fixtures tab lists the ten people, their departments and reporting lines, and the nine assignor → assignee pairs (FX-01 … FX-09) the cases refer to. Set that org up first, or map each fixture reference to whoever plays that part in your data and write the mapping on the Fixtures tab.
A20: The one to get right | B20: EMP-ENG-2 sits in Engineering but reports to the Design manager. That pair (FX-07) is what proves a reporting line beats a department boundary — without it, the cross-department tests cannot tell a real gate from a wrongly raised one.
A21: Departments | B21: At least two, each with a head who can approve — the SENDING head and the RECEIVING head are different people and their order matters.
A23: The rules being tested, in one place
A24: Deadline model | B24: Inside the reporting line → a negotiable BUDGET in hours and minutes. Outside it → a FIXED date set by the assigning side. The department does not decide this; the reporting line does.
A25: Approval gate | B25: A cross-department gate is raised only when NO reporting line reaches the assignee — and a DIRECT manager clears it even across a boundary, while a skip-level manager does not. Assigning to somebody senior raises the upward gate instead, and the senior assignee approves it themselves.
A26: Gate order | B26: Sending department first, receiving department second. Clearing the sender is what makes the receiver's stage current.
A27: Budget loop | B27: Symmetric: whoever is waited on may accept or counter, and every counter passes the turn to the other side. A counter from the assignee goes to the person who decides their hours — their PRIMARY MANAGER, not whoever sent the work. There is no reject; agreement is the only exit.
A28: More time | B28: Two different questions with two different owners. How many HOURS this person gets — their manager. When the work is DUE — the assignor. The hours are asked first, and only the manager escalates the date.
A29: Timer | B29: Elapsed is derived from timestamps, so it survives reloads and throttled tabs. One timer at a time. You cannot start a clock while away, but you can always stop one. Past the deadline the clock will not run — and nothing else is blocked.
A30: Review | B30: Whoever assigned the task reviews it, alone, and their approval is final. Rework returns the task with the time that was LEFT when it was handed in — finishing early is what earns rework time.
A32: Legend
A33: Not run | B33: Not yet attempted. The starting value of every row.
A34: Pass | B34: Behaves exactly as the Expected result column describes.
A35: Fail | B35: Differs. Record what actually happened and raise a defect.
A36: Blocked | B36: Cannot be tested — environment, a missing fixture, or an earlier E2E step that failed.
A37: N/A | B37: Not applicable to this build or environment. Say why in Notes.
A38: Priority | B38: High — must pass before release. Medium — should pass. Low — cosmetic.
A40: How to report
A41: Quote the ID | B41: Test IDs are stable. Quote them in defect reports — “XD-07 fails” locates the case exactly.
A42: Say which surface | B42: For anything involving the bar, state whether the behaviour was seen on /home, on /tasks, or on the task page. A defect that appears on one surface only is a different defect from one that appears on both.
A43: Record the figures | B43: Timer and deadline cases turn on numbers. Write the actual figures into Actual result — “showed 3:00 for 30 seconds of work” is a report; “timer wrong” is not.

Sheet Summary
A1: Summary — progress and result
A2: Counts come from the Status column on each tab. Nothing here is typed by hand.
A3: Module | B3: Cases | C3: Pass | D3: Fail | E3: Blocked | F3: N/A | G3: Not run | H3: % complete | I3: What it covers
A4: Creation | B4: =COUNTA('Creation'!$A$4:$A$17) -> 14 | C4: =COUNTIF('Creation'!$I$4:$I$17,"Pass") -> 0 | D4: =COUNTIF('Creation'!$I$4:$I$17,"Fail") -> 0 | E4: =COUNTIF('Creation'!$I$4:$I$17,"Blocked") -> 0 | F4: =COUNTIF('Creation'!$I$4:$I$17,"N/A") -> 0 | G4: =COUNTIF('Creation'!$I$4:$I$17,"Not run") -> 14 | H4: =IFERROR((B4-G4)/B4,0) -> 0 | I4: Raising a task: the form, the picker, the relationship and the deadline model it chooses
A5: Gates | B5: =COUNTA('Gates'!$A$4:$A$16) -> 13 | C5: =COUNTIF('Gates'!$I$4:$I$16,"Pass") -> 0 | D5: =COUNTIF('Gates'!$I$4:$I$16,"Fail") -> 0 | E5: =COUNTIF('Gates'!$I$4:$I$16,"Blocked") -> 0 | F5: =COUNTIF('Gates'!$I$4:$I$16,"N/A") -> 0 | G5: =COUNTIF('Gates'!$I$4:$I$16,"Not run") -> 13 | H5: =IFERROR((B5-G5)/B5,0) -> 0 | I5: Approval before the work lands: no gate, upward, and the two-stage cross-department gate
A6: Acceptance | B6: =COUNTA('Acceptance'!$A$4:$A$11) -> 8 | C6: =COUNTIF('Acceptance'!$I$4:$I$11,"Pass") -> 0 | D6: =COUNTIF('Acceptance'!$I$4:$I$11,"Fail") -> 0 | E6: =COUNTIF('Acceptance'!$I$4:$I$11,"Blocked") -> 0 | F6: =COUNTIF('Acceptance'!$I$4:$I$11,"N/A") -> 0 | G6: =COUNTIF('Acceptance'!$I$4:$I$11,"Not run") -> 8 | H6: =IFERROR((B6-G6)/B6,0) -> 0 | I6: The assignee taking the work on — accepting terms, refusing terms, confirming receipt
A7: Budget | B7: =COUNTA('Budget'!$A$4:$A$11) -> 8 | C7: =COUNTIF('Budget'!$I$4:$I$11,"Pass") -> 0 | D7: =COUNTIF('Budget'!$I$4:$I$11,"Fail") -> 0 | E7: =COUNTIF('Budget'!$I$4:$I$11,"Blocked") -> 0 | F7: =COUNTIF('Budget'!$I$4:$I$11,"N/A") -> 0 | G7: =COUNTIF('Budget'!$I$4:$I$11,"Not run") -> 8 | H7: =IFERROR((B7-G7)/B7,0) -> 0 | I7: The time-budget loop: counter, whose turn, no reject, agreement
A8: Deadline | B8: =COUNTA('Deadline'!$A$4:$A$14) -> 11 | C8: =COUNTIF('Deadline'!$I$4:$I$14,"Pass") -> 0 | D8: =COUNTIF('Deadline'!$I$4:$I$14,"Fail") -> 0 | E8: =COUNTIF('Deadline'!$I$4:$I$14,"Blocked") -> 0 | F8: =COUNTIF('Deadline'!$I$4:$I$14,"N/A") -> 0 | G8: =COUNTIF('Deadline'!$I$4:$I$14,"Not run") -> 11 | H8: =IFERROR((B8-G8)/B8,0) -> 0 | I8: Where the date comes from, asking for more time, and the deadline's block on the clock
A9: Timer | B9: =COUNTA('Timer'!$A$4:$A$15) -> 12 | C9: =COUNTIF('Timer'!$I$4:$I$15,"Pass") -> 0 | D9: =COUNTIF('Timer'!$I$4:$I$15,"Fail") -> 0 | E9: =COUNTIF('Timer'!$I$4:$I$15,"Blocked") -> 0 | F9: =COUNTIF('Timer'!$I$4:$I$15,"N/A") -> 0 | G9: =COUNTIF('Timer'!$I$4:$I$15,"Not run") -> 12 | H9: =IFERROR((B9-G9)/B9,0) -> 0 | I9: Real elapsed time, one timer at a time, presence and the three surfaces agreeing
A10: Submission | B10: =COUNTA('Submission'!$A$4:$A$20) -> 17 | C10: =COUNTIF('Submission'!$I$4:$I$20,"Pass") -> 0 | D10: =COUNTIF('Submission'!$I$4:$I$20,"Fail") -> 0 | E10: =COUNTIF('Submission'!$I$4:$I$20,"Blocked") -> 0 | F10: =COUNTIF('Submission'!$I$4:$I$20,"N/A") -> 0 | G10: =COUNTIF('Submission'!$I$4:$I$20,"Not run") -> 17 | H10: =IFERROR((B10-G10)/B10,0) -> 0 | I10: Handing work in, the review chain, rework and its deadline, approval
A11: E2E same-dept | B11: =COUNTA('E2E same-dept'!$A$4:$A$14) -> 11 | C11: =COUNTIF('E2E same-dept'!$I$4:$I$14,"Pass") -> 0 | D11: =COUNTIF('E2E same-dept'!$I$4:$I$14,"Fail") -> 0 | E11: =COUNTIF('E2E same-dept'!$I$4:$I$14,"Blocked") -> 0 | F11: =COUNTIF('E2E same-dept'!$I$4:$I$14,"N/A") -> 0 | G11: =COUNTIF('E2E same-dept'!$I$4:$I$14,"Not run") -> 11 | H11: =IFERROR((B11-G11)/B11,0) -> 0 | I11: Run in order, top to bottom. MGR-DES → EMP-DES-1 (FX-01), creation through completion
A12: E2E cross-dept | B12: =COUNTA('E2E cross-dept'!$A$4:$A$14) -> 11 | C12: =COUNTIF('E2E cross-dept'!$I$4:$I$14,"Pass") -> 0 | D12: =COUNTIF('E2E cross-dept'!$I$4:$I$14,"Fail") -> 0 | E12: =COUNTIF('E2E cross-dept'!$I$4:$I$14,"Blocked") -> 0 | F12: =COUNTIF('E2E cross-dept'!$I$4:$I$14,"N/A") -> 0 | G12: =COUNTIF('E2E cross-dept'!$I$4:$I$14,"Not run") -> 11 | H12: =IFERROR((B12-G12)/B12,0) -> 0 | I12: Run in order, top to bottom. MGR-DES → EMP-ENG-1 (FX-06), both gates through completion
A13: Bar parity | B13: =COUNTA('Bar parity'!$A$4:$A$15) -> 12 | C13: =COUNTIF('Bar parity'!$I$4:$I$15,"Pass") -> 0 | D13: =COUNTIF('Bar parity'!$I$4:$I$15,"Fail") -> 0 | E13: =COUNTIF('Bar parity'!$I$4:$I$15,"Blocked") -> 0 | F13: =COUNTIF('Bar parity'!$I$4:$I$15,"N/A") -> 0 | G13: =COUNTIF('Bar parity'!$I$4:$I$15,"Not run") -> 12 | H13: =IFERROR((B13-G13)/B13,0) -> 0 | I13: The home page's active-work bar must behave exactly as the Tasks surfaces do
A14: Visibility | B14: =COUNTA('Visibility'!$A$4:$A$13) -> 10 | C14: =COUNTIF('Visibility'!$I$4:$I$13,"Pass") -> 0 | D14: =COUNTIF('Visibility'!$I$4:$I$13,"Fail") -> 0 | E14: =COUNTIF('Visibility'!$I$4:$I$13,"Blocked") -> 0 | F14: =COUNTIF('Visibility'!$I$4:$I$13,"N/A") -> 0 | G14: =COUNTIF('Visibility'!$I$4:$I$13,"Not run") -> 10 | H14: =IFERROR((B14-G14)/B14,0) -> 0 | I14: Who sees what, and who may act — scopes, gated work and permission boundaries
A15: All modules | B15: =SUM(B4:B14) -> 127 | C15: =SUM(C4:C14) -> 0 | D15: =SUM(D4:D14) -> 0 | E15: =SUM(E4:E14) -> 0 | F15: =SUM(F4:F14) -> 0 | G15: =SUM(G4:G14) -> 127 | H15: =IFERROR((B15-G15)/B15,0) -> 0 | I15: The two E2E tabs are scripted runs — a failed step blocks the ones beneath it.
A17: Sign-off
A18: Tested by | C18: Date | I18: Who ran the pack.
A19: Reviewed by | C19: Date | I19: Who checked the failures and the retests.
A20: Released by | C20: Date | I20: Sign only when every High case passes and both E2E runs complete end to end.

Sheet Fixtures
A1: Fixtures — the org these tests assume
A2: Set this up before running anything, or map each reference to your own people in the last column.
A3: Ref | B3: Person | C3: Department | D3: Reports to | E3: Why they are in the fixture | F3: Who plays this in your data
A4: CE | B4: Chief executive | C4: — | D4: nobody | E4: Top of the reporting line. Needed for the ceo_direct review flow and for tasks with no parent.
A5: ADMIN | B5: System administrator | C5: Operations | D5: CE | E5: Passes the admin-console check. Needed for the Private/Team lens and the settings console.
A6: HOD-DES | B6: Head of Design | C6: Design | D6: CE | E6: Department head for Design — the SENDING approver on cross-department work leaving Design.
A7: HOD-ENG | B7: Head of Engineering | C7: Engineering | D7: CE | E7: Department head for Engineering — the RECEIVING approver on work arriving into Engineering.
A8: MGR-DES | B8: Design manager | C8: Design | D8: HOD-DES | E8: Assignor for most of this pack. Manages EMP-DES-1, EMP-DES-2 and (deliberately) EMP-ENG-2.
A9: EMP-DES-1 | B9: Designer 1 | C9: Design | D9: MGR-DES | E9: The main assignee. Same department, inside the line.
A10: EMP-DES-2 | B10: Designer 2 | C10: Design | D10: MGR-DES | E10: A PEER of EMP-DES-1 — same department, no reporting line between them.
A11: MGR-ENG | B11: Engineering manager | C11: Engineering | D11: HOD-ENG | E11: The assignee's primary manager on cross-department work — decides EMP-ENG-1's hours.
A12: EMP-ENG-1 | B12: Engineer 1 | C12: Engineering | D12: MGR-ENG | E12: The cross-department assignee. No line reaches them from Design.
A13: EMP-ENG-2 | B13: Engineer 2 | C13: Engineering | D13: MGR-DES | E13: DELIBERATE ODDITY: sits in Engineering but reports directly to the Design manager. Proves a reporting line beats a department boundary.
A15: Assignment matrix — what each pair should produce
A16: Ref | B16: Assignor → assignee | C16: Relationship | D16: Deadline model | E16: Approval gate | F16: Why
A17: FX-01 | B17: MGR-DES → EMP-DES-1 | C17: in_line | D17: Budget (negotiable window) | E17: None | F17: The assignee reports to the creator. Same department, but the line is what decides.
A18: FX-02 | B18: HOD-DES → EMP-DES-1 | C18: in_line | D18: Budget (negotiable window) | E18: None | F18: Skip-level inside the same department: still inside the reporting closure.
A19: FX-03 | B19: EMP-DES-1 → EMP-DES-2 | C19: outside_line | D19: Fixed date | E19: None | F19: Same department, no line between peers. Sharing a department grants nothing.
A20: FX-04 | B20: EMP-DES-1 → MGR-DES | C20: outside_line | D20: Fixed date | E20: Upward — the senior assignee approves | F20: Assigning to somebody senior raises the upward gate; the approver is the senior assignee themselves.
A21: FX-05 | B21: EMP-DES-1 → self | C21: self | D21: Budget, proposed by the assignee | E21: None to start; the MANAGER decides the budget | F21: A self task's window is proposed by the assignee and decided by their manager.
A22: FX-06 | B22: MGR-DES → EMP-ENG-1 | C22: cross_department | D22: Fixed date | E22: Cross-department — HOD-DES then HOD-ENG | F22: No line reaches the assignee and a boundary is crossed. Both heads approve.
A23: FX-07 | B23: MGR-DES → EMP-ENG-2 | C23: in_line | D23: Budget (negotiable window) | E23: None | F23: THE REGRESSION CASE: a direct report in another department. The line spans the boundary, so no gate and no fixed date.
A24: FX-08 | B24: HOD-DES → EMP-ENG-2 | C24: in_line | D24: Budget (negotiable window) | E24: Cross-department — both heads | F24: Skip-level ACROSS a boundary: budget (full line) AND two approvers (only a DIRECT manager clears the gate). Both, and that is correct.
A25: FX-09 | B25: MGR-DES → EMP-DES-1 + EMP-ENG-1 | C25: cross_department | D25: Fixed date | E25: Cross-department | F25: Mixed list: one assignee outside the line is enough to move the whole task to the stricter model.
A27: Each matrix row is itself a test: create a task for that pair and the form's own forecast sentence must describe the relationship named here. FX-07 and FX-08 are the two that catch a department boundary being allowed to speak over a reporting line.

Sheet Creation
A1: Creation — test cases
A2: Raising a task: the form, the picker, the relationship and the deadline model it chooses · 14 cases
A3: Test ID | B3: Area / step | C3: What is under test | D3: Priority | E3: Pre-condition | F3: Test steps | G3: Expected result | H3: Actual result | I3: Status | J3: Tested by | K3: Date | L3: Notes / defect ref
A4: TC-01 | B4: Create — entry points | C4: Reaching the create form | D4: High | E4: Signed in as MGR-DES with permission to create tasks. | F4: 1. From /home, press New task in the QuickAssign card. 2. Note the URL. 3. Go back, open /tasks and press New task on the tab row. 4. Compare the two forms. | G4: Both routes land on /tasks/new and render the identical form. There is no second, older create form behind either button. | I4: Not run
A5: TC-02 | B5: Create — required fields | C5: Title and assignee are enforced | D5: High | E5: On /tasks/new as MGR-DES. | F5: 1. Press the create button with everything empty. 2. Enter a title only and press create. 3. Add an assignee and create. | G5: Creation is refused until a title and at least one assignee are present. The refusal for a missing assignee reads "Assign to at least one person." — a sentence, not a field name such as "assigneeIds required". | I5: Not run
A6: TC-03 | B6: Create — assignee picker | C6: Search, department and role filters | D6: Medium | E6: On /tasks/new as MGR-DES. | F6: 1. Search an employee by name. 2. Filter by department = Engineering. 3. Filter by role. 4. Clear both filters. 5. Look for your own name in the list. | G6: Search and both filters narrow the list correctly. Your own name is NOT offered (a task for yourself is the Self type). Only people this viewer may be offered are listed — the picker and the write agree. | I6: Not run
A7: TC-04 | B7: Create — relationship forecast | C7: The form names the relationship before you commit | D7: High | E7: On /tasks/new as MGR-DES. Use the Fixtures tab. | F7: 1. Pick EMP-DES-1 and read the note under the People group. 2. Change to EMP-ENG-1 and read it again. 3. Change to EMP-ENG-2 and read it again. 4. Add EMP-DES-1 AND EMP-ENG-1 together. | G7: FX-01 shows the in_line forecast ("within your reporting hierarchy… you set a working window"). FX-06 shows the cross-department forecast ("outside your reporting hierarchy and in another department… both department heads approve"). FX-07 shows in_line, NOT cross-department. FX-09 falls to the cross-department wording. | I7: Not run
A8: TC-05 | B8: Create — deadline model | C8: The model follows the relationship, not the department | D8: High | E8: On /tasks/new as MGR-DES. | F8: 1. Pick EMP-DES-1 and look at the Deadline group. 2. Pick EMP-DES-2 as the only assignee (as EMP-DES-1, per FX-03). 3. Pick EMP-ENG-2 (FX-07). 4. Pick EMP-ENG-1 (FX-06). | G8: In-line assignees (FX-01, FX-07) offer a BUDGET — an hours/minutes window. Assignees with no line (FX-03, FX-06) offer a fixed Due date and no budget field. FX-07 in particular must show a budget: a direct report in another department is not a cross-department task. | I8: Not run
A9: TC-06 | B9: Create — budget field | C9: The window is entered as hours and minutes | D9: Medium | E9: Creating an in-line task. | F9: 1. Enter 2h 30m in the budget field. 2. Step the minutes up from 55. 3. Create the task and open it. | G9: The field takes hours and minutes, minutes step in fives and roll into the hour, and the created task carries exactly the window entered. | I9: Not run
A10: TC-07 | B10: Create — fixed date | C10: A date-and-time is required outside the line | D10: Medium | E10: Creating a task for EMP-ENG-1 (FX-06). | F10: 1. Leave the due date empty and try to create. 2. Set a date in the past. 3. Set a valid future date and time and create. | G10: The date is required, a past date is refused or flagged, and the created task carries the exact instant set — date AND time, not a bare date. | I10: Not run
A11: TC-08 | B11: Create — requirements | C11: Acceptance criteria are captured | D11: Medium | E11: On /tasks/new. | F11: 1. Add three requirements. 2. Edit one and remove another. 3. Create the task. 4. Open the task and read the completion checklist. | G11: Requirements are added, edited and removed before creation, and all surviving ones appear on the task in the order entered. | I11: Not run
A12: TC-09 | B12: Create — attachments | C12: Reference files are attached at creation | D12: Medium | E12: On /tasks/new, with a file to hand. | F12: 1. Attach a reference file. 2. Create the task. 3. Open the task's Files tab as the assignee. | G12: The file uploads, is listed on the created task, and the assignee can open it. | I12: Not run
A13: TC-10 | B13: Create — self task | C13: A self task assigns to you | D13: High | E13: Signed in as EMP-DES-1. | F13: 1. Choose the Self type. 2. Note who the assignee list contains. 3. Set a window and create. 4. Open the task. | G13: The task is created with EMP-DES-1 as the assignee even though the picker never offered them. It reads as self-assigned (FX-05), and the window is a proposal waiting on their manager — not an agreed figure. | I13: Not run
A14: TC-11 | B14: Create — project / parent | C14: A task can be created under a parent | D14: Medium | E14: A project or parent task exists. | F14: 1. Set Parent task on the create form. 2. Create. 3. Open the parent. | G14: The new task appears beneath the parent, and the parent's completion progress counts it. | I14: Not run
A15: TC-12 | B15: Create — subtask deadline cap | C15: A subtask cannot outlive its parent | D15: High | E15: A parent task with a deadline. | F15: 1. Create a subtask with a deadline AFTER the parent's. 2. Read the refusal. 3. Set it inside the parent's deadline and create. | G15: The later deadline is refused with the cap explained, naming the parent's deadline. Inside the cap it is accepted. | I15: Not run
... A17: TC-14 | B17: Create — confirmation | C17: The created task lands where the creator expects | D17: High | E17: Any created task. | F17: 1. Create a task for EMP-DES-1. 2. Note where you are taken. 3. Open /tasks as MGR-DES and find it. 4. Sign in as EMP-DES-1 and find it under My tasks. | G17: The creator reaches the created task (or the list with it visible). It appears in the assignee's My tasks and under the assignee's heading in the manager's My team. It is not double-counted. | I17: Not run

Sheet Gates
A1: Gates — test cases
A2: Approval before the work lands: no gate, upward, and the two-stage cross-department gate · 13 cases
A3: Test ID | B3: Area / step | C3: What is under test | D3: Priority | E3: Pre-condition | F3: Test steps | G3: Expected result | H3: Actual result | I3: Status | J3: Tested by | K3: Date | L3: Notes / defect ref
A4: GT-01 | B4: No gate — in line | C4: An in-line task needs no approval | D4: High | E4: MGR-DES creates a task for EMP-DES-1 (FX-01). | F4: 1. Create the task. 2. Read its status immediately. 3. Check for any pending approval on it. | G4: The task goes straight to the assignee — status Assigned (or the budget offer), never Pending approval. No approval record is created. | I4: Not run
A5: GT-02 | B5: Upward gate | C5: Assigning to somebody senior needs their approval | D5: High | E5: EMP-DES-1 creates a task for MGR-DES (FX-04). | F5: 1. Create the task as EMP-DES-1. 2. Read the status and the flow section. 3. Sign in as MGR-DES and find the approval. 4. Approve it. 5. Sign in as somebody else senior and check they were NOT asked. | G5: Status is Pending approval and the flow names MGR-DES as the approver — the senior assignee themselves, not a department head. Only that person can decide it. After approval the task proceeds normally. | I5: Not run
A6: GT-03 | B6: Cross-department gate | C6: Both heads approve, sender first | D6: High | E6: MGR-DES creates a task for EMP-ENG-1 (FX-06). | F6: 1. Create the task. 2. Read the flow section as MGR-DES. 3. Sign in as HOD-ENG and try to approve before HOD-DES has. 4. Sign in as HOD-DES and approve. 5. Return to HOD-ENG and approve. | G6: The flow lists the sending department (HOD-DES) as current and the receiving one (HOD-ENG) as upcoming/waiting. HOD-ENG cannot clear their stage first. Clearing the sender flips the receiver from waiting to pending. After both, the task lands on EMP-ENG-1. | I6: Not run
A7: GT-04 | B7: Cross-department gate | C7: The task is not the assignee's until both approve | D7: High | E7: The FX-06 task at Pending approval. | F7: 1. Sign in as EMP-ENG-1. 2. Look in My tasks. 3. Open the task by its direct URL. 4. Try to confirm receipt or start a timer. | G7: The task is not in their My tasks list as owned work, and the page offers no accept, confirm or start control. Nothing they press can take it on before the gates clear. | I7: Not run
A8: GT-05 | B8: Cross-department gate | C8: The pending assignee is told work is coming | D8: High | E8: Create the FX-06 task with notifications visible for EMP-ENG-1. | F8: 1. Create the task as MGR-DES. 2. Sign in as EMP-ENG-1 and open Notifications immediately. 3. Read the wording. | G8: EMP-ENG-1 receives a notification that work is heading their way, pending approval — NOT a "task assigned" notification. The wording does not claim they have been assigned work that a head can still refuse. | I8: Not run
A9: GT-06 | B9: Cross-department gate | C9: The approvers are notified | D9: Medium | E9: Create the FX-06 task. | F9: 1. Sign in as HOD-DES and check notifications. 2. Approve, then sign in as HOD-ENG and check notifications. | G9: Each head is notified when their own stage becomes current — the receiving head is not asked before the sending head has cleared. | I9: Not run
A10: GT-07 | B10: Cross-department gate | C10: A refusal ends the task honestly | D10: High | E10: The FX-06 task with HOD-DES already approved. | F10: 1. Sign in as HOD-ENG and reject with a reason. 2. Read the task as MGR-DES. 3. Read it as EMP-ENG-1. | G10: Status becomes Assignment rejected. The flow shows the refusing stage as blocked with the reason and the name. Nothing downstream happens, and EMP-ENG-1 never holds the work. | I10: Not run
A11: GT-08 | B11: Cross-department gate | C11: A direct manager across a boundary raises no gate | D11: High | E11: MGR-DES creates a task for EMP-ENG-2 (FX-07). | F11: 1. Create the task. 2. Read the status and the flow. 3. Check whether either head was asked. | G11: No cross-department approval is raised — the reporting line spans the boundary. Neither HOD-DES nor HOD-ENG is asked. The task carries a negotiable budget, not a fixed date. | I11: Not run
A12: GT-09 | B12: Cross-department gate | C12: Skip-level across a boundary gets both | D12: Medium | E12: HOD-DES creates a task for EMP-ENG-2 (FX-08). | F12: 1. Create the task. 2. Read the deadline model on the created task. 3. Read the approval flow. | G12: The task carries a BUDGET (the full reporting line reaches EMP-ENG-2) AND a cross-department approval by both heads (only a direct manager clears the gate). Both at once is the expected answer, not a contradiction. | I12: Not run
A13: GT-10 | B13: Flow section | C13: The flow answers whose turn it is | D13: High | E13: Any gated task. | F13: 1. Open the task and read the flow section. 2. Note whose turn it is, what happens next and why it is waiting. | G13: The flow names the person who owes the next action, what follows, and the reason it is waiting. Exactly one stage is current, or none. Nothing is guessed: where the record names nobody it says "Waiting for department approval" rather than inventing a name. | I13: Not run
A14: GT-11 | B14: Flow section | C14: Cleared stages carry who and when | D14: Medium | E14: A task with at least one approval already given. | F14: 1. Read each cleared stage. | G14: Each done stage names the person who cleared it and when. Timestamps appear only on stages that actually happened. | I14: Not run
A15: GT-12 | B15: Approval — effort estimate | C15: A budget stage asks for a number, not a verdict | D15: Medium | E15: A task whose pending approval is an effort estimate. | F15: 1. Open it as the approver. 2. Read the action offered. | G15: The action reads "Set the time budget", not "Approve or reject" — there are deliberately no approve/reject buttons on a stage that asks for a figure. | I15: Not run
A16: GT-13 | B16: Approval — wrong person | C16: Nobody else can clear a stage | D16: High | E16: A task pending on HOD-ENG. | F16: 1. Sign in as MGR-ENG (not an approver) and open the task. 2. Look for approve/reject controls. 3. If the endpoint is reachable, attempt the write directly. | G16: No approval controls are offered, and a direct attempt is refused by the server — the screen and the write agree about who may decide. | I16: Not run

Sheet Acceptance
A1: Acceptance — test cases
A2: The assignee taking the work on — accepting terms, refusing terms, confirming receipt · 8 cases
A3: Test ID | B3: Area / step | C3: What is under test | D3: Priority | E3: Pre-condition | F3: Test steps | G3: Expected result | H3: Actual result | I3: Status | J3: Tested by | K3: Date | L3: Notes / defect ref
A4: AC-01 | B4: Acceptance — the offer | C4: The assignee is offered the terms | D4: High | E4: An FX-01 budget task just created for EMP-DES-1. | F4: 1. Sign in as EMP-DES-1 and open /home. 2. Read the bar's action. 3. Open the task page and read its action. | G4: Both surfaces offer the same step — "Accept or discuss the time" on the page, and the bar's Approve task / Send for approval pair, which is the same decision. Neither offers a control the other withholds. | I4: Not run
A5: AC-02 | B5: Acceptance — accept as it stands | C5: Accepting the offered window takes the task on | D5: High | E5: As above. | F5: 1. Leave the figure untouched and press Approve task. 2. Read the status. 3. Reload. | G5: One press accepts the terms and takes the task on — no second "Confirm receipt" step. The status advances and survives a reload. | I5: Not run
A6: AC-03 | B6: Acceptance — who may accept | C6: Only an assignee can accept | D6: High | E6: The FX-01 task, unaccepted. | F6: 1. Sign in as MGR-DES (the creator) and open the task. 2. Look for a Confirm receipt or Approve control. 3. Sign in as an unrelated employee and look again. | G6: Neither the creator nor a bystander is offered acceptance. The control is offered to the assignee only — the screen does not offer a write the server would refuse with a 403. | I6: Not run
A7: AC-04 | B7: Acceptance — do not be stricter than the engine | C7: The control is offered even mid-negotiation | D7: High | E7: A budget task whose window is still being agreed. | F7: 1. As the assignee, open the task while the budget is unsettled. 2. Look for the acceptance control. 3. Press it and read any refusal. | G7: The control is offered rather than hidden. If the engine refuses, its own sentence is shown — e.g. asking for a deadline to be proposed and approved first. The screen never renders "Your move" above nothing. | I7: Not run
A8: AC-05 | B8: Acceptance — refusing the terms | C8: There is no decline, but there is a refusal | D8: High | E8: The FX-01 task, unaccepted. | F8: 1. As the assignee, look for a Decline control. 2. Change the figure on the stepper and press Send for approval. 3. Try to send with an empty reason. 4. Send with a reason. | G8: No decline control exists anywhere. Refusing the TERMS is done by countering the window with a required reason. An empty reason is refused. Sending opens the budget negotiation and leaves the task where it was — it is not rejected or returned. | I8: Not run
A9: AC-06 | B9: Acceptance — fixed-date task | C9: A date task is confirmed, not negotiated | D9: High | E9: The FX-06 task, both approvals cleared, as EMP-ENG-1. | F9: 1. Open the task. 2. Look for a budget stepper. 3. Read the action offered on the bar and the page. | G9: There is no budget stepper — the date was set by the assigning side. The action is Confirm receipt, and it is the same on both surfaces. | I9: Not run
A10: AC-07 | B10: Acceptance — start | C10: Confirmed work offers Start | D10: High | E10: A task confirmed but not started. | F10: 1. Read the action on the task page. 2. Read the bar. 3. Press start. | G10: Both say Start work. The clock reads 00:00:00 before the press and begins on it. | I10: Not run
A11: AC-08 | B11: Acceptance — away | C11: Being away suspends your move | D11: High | E11: The assignee has an active break / away duty mode. | F11: 1. Set the assignee away. 2. Open the task and the bar. 3. Check the dashboard "needs action" counts. 4. Try to start the timer. | G11: Whatever the task would otherwise ask — confirm, accept, start, submit — both surfaces show the away sentence instead, and the task is kept OUT of needs-action counts. Starting a timer is refused by the server, not just hidden. | I11: Not run

Sheet Budget
A1: Budget — test cases
A2: The time-budget loop: counter, whose turn, no reject, agreement · 8 cases
A3: Test ID | B3: Area / step | C3: What is under test | D3: Priority | E3: Pre-condition | F3: Test steps | G3: Expected result | H3: Actual result | I3: Status | J3: Tested by | K3: Date | L3: Notes / defect ref
A4: BN-01 | B4: Budget — the loop | C4: Either side may counter or accept | D4: High | E4: An FX-01 budget task, offer outstanding. | F4: 1. As EMP-DES-1, counter with a different figure and a reason. 2. Read whose turn it becomes. 3. As that person, counter again. 4. Read whose turn it becomes. | G4: Every counter passes the turn to the OTHER party. Whoever is waited on may either accept what stands or counter — the same person is never shown an accept control over their own outstanding proposal. | I4: Not run
A5: BN-02 | B5: Budget — who answers a counter | C5: The turn goes to the assignee's MANAGER | D5: High | E5: An FX-06-style task where the assignor is NOT the assignee's manager. Use a task assigned by HOD-DES to EMP-ENG-2 (FX-08), whose manager is MGR-DES. | F5: 1. As the assignee, counter the window. 2. Read who the task now waits on. 3. Sign in as that person and confirm the decision is offered. 4. Sign in as the assignor and confirm it is NOT offered to them. | G5: The counter goes to the person who decides that employee's hours — their primary manager — not to whoever sent the work. The assignor sees it as waiting on somebody else. Where no manager can be resolved it falls back to the assignor, and only then. | I5: Not run
A6: BN-03 | B6: Budget — no reject | C6: Disagreement is a counter, never a refusal | D6: High | E6: A budget negotiation in flight. | F6: 1. Look for a Reject or Decline control at every stage of the loop. | G6: There is none. The only exit is agreement — a refusal that ended the negotiation would leave the work carrying a budget one side never agreed to. | I6: Not run
A7: BN-04 | B7: Budget — agreement | C7: Agreeing settles the task and derives the deadline | D7: High | E7: A budget negotiation in flight. | F7: 1. Accept the figure on the table. 2. Read the task's status and its deadline. 3. Compare with the queue position. | G7: State becomes agreed, work can start, and the task now carries a deadline derived from the window and the queue — the assignee never typed a date. | I7: Not run
A8: BN-05 | B8: Budget — history | C8: Every round is recorded | D8: Medium | E8: A negotiation with at least three rounds. | F8: 1. Open the task's budget history. 2. Read each entry. | G8: Every figure, who proposed it, when, and the reason given, in order. The round count matches the number of proposals. | I8: Not run
A9: BN-06 | B9: Budget — self task | C9: A self task's window is decided by the manager | D9: High | E9: EMP-DES-1 created a self task (FX-05) with a proposed window. | F9: 1. As EMP-DES-1, read the action offered. 2. Sign in as MGR-DES and read theirs. 3. Decide the budget as MGR-DES. 4. Return to EMP-DES-1. | G9: EMP-DES-1 is told the budget is awaiting a decision — they are NOT offered "Propose a deadline" or "Confirm receipt" over a figure they already proposed. MGR-DES is offered "Decide the time budget". After the decision the assignee can proceed. | I9: Not run
A10: BN-07 | B10: Budget — bar parity | C10: The bar's stepper is the panel's control | D10: High | E10: A budget offer outstanding for the viewer. | F10: 1. Change the figure on the bar's stepper; note the value and the rollover behaviour. 2. Open the task page and change it there. 3. Send from the bar; then repeat the exercise sending from the page. | G10: Both surfaces use the same stepper with the same 5-minute steps and hour rollover, and both writes produce the same record — the manager sees no difference between a counter sent from the bar and one sent from the page. | I10: Not run
A11: BN-08 | B11: Budget — refusal message | C11: A refused write says why, where it happened | D11: Medium | E11: Any state where the engine refuses the accept. | F11: 1. Trigger the refusal from the bar. 2. Trigger the same refusal from the task page. | G11: The engine's own sentence is shown once, beside the control that caused it — on the row for Approve, in the panel for Send. The same sentence appears on the task page. | I11: Not run

Sheet Deadline
A1: Deadline — test cases
A2: Where the date comes from, asking for more time, and the deadline's block on the clock · 11 cases
A3: Test ID | B3: Area / step | C3: What is under test | D3: Priority | E3: Pre-condition | F3: Test steps | G3: Expected result | H3: Actual result | I3: Status | J3: Tested by | K3: Date | L3: Notes / defect ref
A4: DL-01 | B4: Deadline — derived vs set | C4: Where the date comes from | D4: High | E4: One budget task (FX-01) and one fixed-date task (FX-06). | F4: 1. Open each task's deadline surface. 2. Read what each says about where the date came from. | G4: The budget task's date is derived from the agreed window and the queue and is not typed by anybody. The fixed-date task's is the instant the assigning side set. Neither is described as the other. | I4: Not run
A5: DL-02 | B5: Deadline — proposal | C5: A proposed date waits on the creator | D5: Medium | E5: A task where the assignee may propose a date (deadline state unset, status assigned). | F5: 1. As the assignee, propose a date. 2. Read the action on both sides. 3. As the creator, decide it. | G5: The assignee's action becomes "Awaiting decision"; the creator's becomes "Decide deadline" pointing at the deadline page. The decision settles it. | I5: Not run
A6: DL-03 | B6: Deadline — counter | C6: A countered date waits on the assignee | D6: Medium | E6: A proposal the creator has countered. | F6: 1. As the creator, counter the proposed date. 2. Read both sides' actions. 3. Respond as the assignee. | G6: The assignee is offered "Respond to counter"; the creator sees "Awaiting response". Responding settles or continues the loop. | I6: Not run
A7: DL-04 | B7: Deadline — more time, step 1 | C7: The assignee asks their MANAGER for hours | D7: High | E7: An in-progress task where the assignee needs longer. | F7: 1. As the assignee, use Request more time (from the bar's clock or the deadline page). 2. Enter the extra hours and a reason and send. 3. Read who the request went to. | G7: The request goes to the assignee's primary manager as a request for HOURS — measured in working seconds — not to the assignor as a request to move the date. | I7: Not run
A8: DL-05 | B8: Deadline — more time, step 2 | C8: The manager grants hours if they fit | D8: High | E8: A pending hours request whose extra time fits inside the committed date. | F8: 1. Sign in as the manager and open the request. 2. Read what the product says about whether it fits. 3. Grant it. 4. Check the task's deadline. | G8: The manager is told the hours fit and may simply grant them. The budget increases and the committed DATE does not move — the assignor is not consulted for a change that never needed them. | I8: Not run
A9: DL-06 | B9: Deadline — more time, step 3 | C9: The manager escalates when it does not fit | D9: High | E9: A pending hours request whose extra time cannot fit before the committed date. | F9: 1. Sign in as the manager and open the request. 2. Read the product's assessment. 3. Escalate the date to the assignor. 4. Sign in as the assignor and read what they were asked. | G9: The manager is told the hours do not fit and must ask the assignor to move the date. The escalation carries the earliest date the employee can actually achieve — the assignee never guesses a date, and the manager never moves a commitment they did not make. | I9: Not run
A10: DL-07 | B10: Deadline — confirmation | C10: An approved extension comes back for confirmation | D10: Medium | E10: An approved time-budget extension. | F10: 1. As the assignee, read the task after the approval. 2. Confirm the extension. 3. Read the budget and the timeline. | G10: The approved extension is confirmed by the assignee and the new figure is what the task then runs on. The extension timeline records the request, the decision and the confirmation as separate events. | I10: Not run
A11: DL-08 | B11: Deadline — timer block | C11: Past the deadline the clock stops | D11: High | E11: A task whose deadline has passed with time still banked. | F11: 1. Open the task and the bar. 2. Try to start the timer. 3. Read the message. 4. Check the banked figure. | G11: The timer will not run and both surfaces say why. The banked figure is unchanged — time already worked is never removed. If a session was running when the deadline passed, it stops. | I11: Not run
A12: DL-09 | B12: Deadline — what is NOT blocked | C12: Everything else still works past the deadline | D12: High | E12: The same overdue task. | F12: 1. Submit the work. 2. Post in the task chat. 3. Request more time. | G12: All three still work. Only the timer is gated — blocking submission would trap somebody who had finished the work. | I12: Not run
A13: DL-10 | B13: Deadline — unblock | C13: An approved extension unblocks without a second write | D13: High | E13: The overdue, blocked task with an extension approved and confirmed. | F13: 1. Approve and confirm an extension that moves the due date into the future. 2. Return to the task WITHOUT any other action. 3. Start the timer. | G13: The block clears on the next render because the answer is recomputed from the current deadline. There is no stuck "blocked" flag needing a separate clear. | I13: Not run
A14: DL-11 | B14: Deadline — extension records | C14: Requests and decisions are listed | D14: Medium | E14: A task with at least one budget extension and one deadline extension. | F14: 1. Open the extension timeline. 2. Compare the two kinds of record. | G14: Hours requests and date changes are recorded as separate things with separate approvers — never merged into one "extension" entry. | I14: Not run

Sheet Timer
A1: Timer — test cases
A2: Real elapsed time, one timer at a time, presence and the three surfaces agreeing · 12 cases
A3: Test ID | B3: Area / step | C3: What is under test | D3: Priority | E3: Pre-condition | F3: Test steps | G3: Expected result | H3: Actual result | I3: Status | J3: Tested by | K3: Date | L3: Notes / defect ref
A4: TM-01 | B4: Timer — start | C4: Starting records a real session | D4: High | E4: A confirmed task assigned to the viewer. | F4: 1. Press start on the task page. 2. Watch the clock for 60 seconds against a stopwatch. 3. Pause. 4. Open the work log. | G4: The clock counts real seconds — 60 seconds of work reads about 1:00, not more. The committed session matches the elapsed time; it is never rounded up to a whole minute. | I4: Not run
A5: TM-02 | B5: Timer — short session | C5: Ten seconds commits as ten seconds | D5: High | E5: A confirmed task. | F5: 1. Start, wait 10 seconds, pause. 2. Read the total. 3. Repeat twice more. | G5: Each 10-second session adds about 10 seconds. Three of them total roughly 30 seconds — NOT 3:00. A commit is never floored to 60 seconds. | I5: Not run
A6: TM-03 | B6: Timer — reload | C6: Elapsed survives a reload | D6: High | E6: A running timer. | F6: 1. Note the clock. 2. Reload the page. 3. Compare. 4. Close the tab, reopen the app, compare again. | G6: The figure continues from where it was. It does not reset to zero and does not jump. | I6: Not run
A7: TM-04 | B7: Timer — background | C7: A throttled tab does not lose time | D7: High | E7: A running timer. | F7: 1. Switch to another application for five minutes. 2. Return and read the clock. 3. Pause and check the committed session. | G7: The clock has advanced by the full five minutes — elapsed is derived from timestamps, so a throttled or sleeping tab catches up rather than losing the time. | I7: Not run
A8: TM-05 | B8: Timer — one at a time | C8: Starting a second task pauses the first | D8: High | E8: Two tasks assigned to the viewer, both startable. | F8: 1. Start task A and let it run. 2. Start task B. 3. Read both clocks and both work logs. | G8: A is paused and its session committed; B runs. Two timers are never running at once, and no time is lost or double-counted in the handover. | I8: Not run
A9: TM-06 | B9: Timer — surfaces agree | C9: Bar, task page and top-bar pill show one figure | D9: High | E9: A running timer. | F9: 1. Read the figure on the home bar, the task page and the top-bar pill at the same moment. 2. Reload and read all three again. | G9: All three agree, before and after a reload. A run in progress never vanishes on one surface while showing on another. | I9: Not run
A10: TM-07 | B10: Timer — resume | C10: Resuming continues from the banked total | D10: High | E10: A task with time banked and the timer paused. | F10: 1. Note the banked figure. 2. Resume. 3. Watch the first few seconds closely. | G10: The clock continues from the banked total. It does not flash the previous run's minutes and then drop them, and it does not restart at zero. | I10: Not run
A11: TM-08 | B11: Timer — presence gate | C11: You cannot start a clock while away | D11: High | E11: The viewer on a break / away. | F11: 1. Try to start a timer from the task page. 2. Try from the home bar. 3. Read the refusal. 4. Now try to PAUSE a session that was already running. | G11: Both surfaces refuse the start with the same sentence, and the refusal comes from the server — not merely a hidden button. Pausing is always allowed, so nobody is stranded with a running clock. | I11: Not run
A12: TM-09 | B12: Timer — blocked display | C12: A blocked clock keeps its figure | D12: High | E12: A task past its deadline with time banked. | F12: 1. Open the home bar and the task page. 2. Read the clock on each. | G12: Both keep showing the banked figure, in amber. Neither replaces the clock with a bare "Blocked" pill. | I12: Not run
A13: TM-10 | B13: Timer — not yours | C13: Somebody else's task shows a clock you cannot run | D13: Medium | E13: A task assigned to another person. | F13: 1. Open it and look at the timer area. | G13: The clock is rendered as plain text, not a control, and pressing it does nothing. It occupies the same space as an interactive one so the row does not change shape. | I13: Not run
A14: TM-11 | B14: Timer — work commits | C14: Sessions are listed against the task | D14: Medium | E14: A task with several sessions. | F14: 1. Open the task's work log / day commits. 2. Compare with the day's total. | G14: Each session is listed with its start, end and duration, and the sum matches the task's logged total. | I14: Not run
A15: TM-12 | B15: Timer — slow network | C15: A slow start still reports honestly | D15: Medium | E15: Network throttled to Slow 3G. | F15: 1. Press start and wait. 2. Read what the button and the clock do. 3. Let it settle and reload. | G15: Either the timer starts, or a clear refusal is shown. The screen never shows a running clock that the server did not record — the state after a reload is the truth. | I15: Not run

Sheet Submission
A1: Submission — test cases
A2: Handing work in, the review chain, rework and its deadline, approval · 17 cases
A3: Test ID | B3: Area / step | C3: What is under test | D3: Priority | E3: Pre-condition | F3: Test steps | G3: Expected result | H3: Actual result | I3: Status | J3: Tested by | K3: Date | L3: Notes / defect ref
A4: SB-01 | B4: Submit — the route | C4: Submitting is offered where work is in progress | D4: High | E4: An in-progress task assigned to the viewer. | F4: 1. Read the action on the task page and on the home bar. 2. Follow it. | G4: Both say the work is ready to submit and lead to the submission surface for that task. | I4: Not run
A5: SB-02 | B5: Submit — note and files | C5: A submission carries what was done | D5: High | E5: An in-progress task. | F5: 1. Submit with a note and two attachments. 2. Open the task as the reviewer. | G5: The note and both files are attached to the submission and visible to the reviewer, with who submitted and when. | I5: Not run
A6: SB-03 | B6: Submit — note required rule | C6: The note rule is enforced when set | D6: Medium | E6: As ADMIN, set the submission-note rule to Required in the settings console. | F6: 1. Submit with an empty note. 2. Read the refusal. 3. Add a note and submit. 4. Set the rule back to Optional and submit another task with no note. | G6: With the rule Required an empty note is refused; with it Optional the submission goes through. The default is Optional — an unsaved settings document changes nothing. | I6: Not run
A7: SB-04 | B7: Submit — requirements rule | C7: Outstanding criteria behave as configured | D7: High | E7: A task with unsatisfied requirements. Test at each setting of the requirements rule. | F7: 1. With the rule Off (the default), submit — note what happens. 2. Set it to Warn and submit again. 3. Set it to Block and submit again. 4. Satisfy the requirements and submit. | G7: Off: the submission goes through and criteria are reference for the reviewer only. Warn: it goes through and names what is unfinished. Block: it is refused while anything is outstanding. A task with no criteria is unaffected at every setting. | I7: Not run
A8: SB-05 | B8: Submit — timer rule | C8: Effort can be made a precondition | D8: Medium | E8: A task with no logged time. Set the timer-before-submit rule to Require. | F8: 1. Submit with no time logged. 2. Log some time and submit. 3. Set the rule back to Allow and submit a task with no time. | G8: With Require, a submission with no recorded effort is refused. With Allow (the default) it goes through. | I8: Not run
A9: SB-06 | B9: Submit — project completion | C9: A project cannot close over unfinished work | D9: High | E9: A parent task whose subtasks claim its requirements, with one subtask still open. | F9: 1. Try to submit the parent. 2. Read the progress figure on the parent. 3. Complete the subtask and read it again. 4. Reopen the subtask. | G9: The submission is refused while a claiming subtask is open, and the progress figure on screen matches the server's answer exactly. Completing the subtask satisfies the requirement; reopening it un-satisfies it again with no separate action. | I9: Not run
A10: SB-07 | B10: Submit — delegated requirement | C10: A delegated tick belongs to the subtask | D10: Medium | E10: A parent requirement claimed by a live subtask. | F10: 1. As the parent's owner, try to tick that requirement directly. 2. Read what the screen says. | G10: The parent's owner can see the state but cannot assert it — the authority moved to the subtask that claimed it. | I10: Not run
A11: SB-08 | B11: Review — the chain | C11: The assigner reviews, alone | D11: High | E11: A submitted task (MGR-DES assigned it, EMP-DES-1 submitted). | F11: 1. Sign in as MGR-DES and open the task. 2. Read the action. 3. Sign in as HOD-DES and check whether they are asked. 4. Sign in as the submitter and check. | G11: MGR-DES — the assigner — is offered "Review submission", and their approval is final. Nobody above them is asked. The submitter is not offered a review of their own work; they see "Awaiting review". | I11: Not run
A12: SB-09 | B12: Review — cross-department | C12: The assigner reviews across a boundary too | D12: High | E12: The FX-06 task submitted by EMP-ENG-1. | F12: 1. Sign in as MGR-DES (the assigner, in another department) and read the action. 2. Check whether MGR-ENG or either head is asked to review. | G12: MGR-DES reviews it. Neither department head is in the chain — the review follows who assigned the work, not the departments it crossed. | I12: Not run
A13: SB-10 | B13: Review — approve | C13: Approval completes the task | D13: High | E13: A submission awaiting review. | F13: 1. Approve it. 2. Read the task's status. 3. Read it in the task list. 4. Check the assignee's score ledger. | G13: The task becomes Completed. In the list it drops below all live work and its priority column shows a dash. The scoring entry for the completion is written once. | I13: Not run
A14: SB-11 | B14: Review — rework | C14: Rework returns the work with time to fix it | D14: High | E14: A submission awaiting review. Record the task's deadline and the exact submission time first. | F14: 1. Note the deadline and the submitted-at time; compute deadline − submittedAt. 2. Send it back for rework with a note (and any required items). 3. Note the moment you sent it back. 4. Read the new deadline as the assignee. | G14: The task returns to In progress for the assignee, and the new deadline is the moment it was sent back PLUS the leftover time they had when they handed it in. Submitting an hour early gives an hour to redo it; a minute early gives a minute. | I14: Not run
A15: SB-12 | B15: Review — rework counter | C15: Rework is not scored as a rejection | D15: High | E15: A task sent back for rework. | F15: 1. Send it back for rework. 2. Check the assignee's rework counter and their score. 3. Compare with a task that was REJECTED. | G15: Rework increments the rework counter and takes the rework deduction. It is not recorded as a rejection — the two are different decisions with different effects. | I15: Not run
... A20: SB-17 | B20: Review — history | C20: The submission history is complete | D20: Medium | E20: A task with a submission, a rework and a resubmission. | F20: 1. Open the task's history. | G20: Every submission, review, rework request and resubmission appears in order with its author, time and text. | I20: Not run

Sheet E2E same-dept
A1: E2E same-dept — scripted run
A2: Run in order, top to bottom. MGR-DES → EMP-DES-1 (FX-01), creation through completion · 11 steps
A3: Test ID | B3: Area / step | C3: What is under test | D3: Priority | E3: Pre-condition | F3: Test steps | G3: Expected result | H3: Actual result | I3: Status | J3: Tested by | K3: Date | L3: Notes / defect ref
A4: SD-01 | B4: Step 1 · Create | C4: MGR-DES raises work for EMP-DES-1 | D4: High | E4: Signed in as MGR-DES. Fixture FX-01. | F4: 1. /tasks/new → title "SD E2E — same department", a description, two requirements, one attachment. 2. Assignee: EMP-DES-1. 3. Read the relationship forecast. 4. Set the budget to 2h 00m and create. | G4: The forecast is the in_line wording and the form offers a BUDGET. The task is created with no approval gate and lands with EMP-DES-1 immediately. | I4: Not run
A5: SD-02 | B5: Step 2 · Assignee sees it | C5: The work reaches the right lists | D5: High | E5: Signed in as EMP-DES-1. | F5: 1. Open /home and read the bar. 2. Open /tasks under My tasks. 3. Sign back in as MGR-DES and look under My team. | G5: The task is on the bar and in EMP-DES-1's My tasks. In MGR-DES's My team it sits under EMP-DES-1's heading. It does NOT appear under MGR-DES's own name anywhere. | I5: Not run
A6: SD-03 | B6: Step 3 · Counter the window | C6: The assignee asks for longer | D6: High | E6: As EMP-DES-1, on the bar. | F6: 1. Change the stepper to 3h 00m. 2. Read the button label. 3. Press it, write a reason, send. 4. Read the task's state on both surfaces. | G6: The label becomes "Send for approval", the reason panel opens off the row, and the counter is recorded. The task waits on the person who decides EMP-DES-1's hours — here MGR-DES, who is both manager and assignor. | I6: Not run
A7: SD-04 | B7: Step 4 · Settle the budget | C7: The manager agrees the figure | D7: High | E7: Signed in as MGR-DES. | F7: 1. Open the task and read the offered decision. 2. Accept 3h 00m. 3. Read the deadline that appears. | G7: The budget settles at 3h 00m and a deadline is derived from the window and the queue. Neither party typed a date. | I7: Not run
A8: SD-05 | B8: Step 5 · Take it on | C8: The assignee accepts and starts | D8: High | E8: Signed in as EMP-DES-1. | F8: 1. Accept / confirm as offered on the bar. 2. Read the deadline block on the bar. 3. Press start. | G8: Acceptance takes one press, the deadline block shows date and time throughout, and the clock starts from 00:00:00. | I8: Not run
A9: SD-06 | B9: Step 6 · Work | C9: Time accrues honestly | D9: High | E9: Timer running. | F9: 1. Work 2 minutes, pause, resume, work 1 more, pause. 2. Compare the total with a stopwatch. 3. Reload and compare again. 4. Read the same figure on the task page and the top-bar pill. | G9: The total is about 3 minutes on every surface, before and after a reload. | I9: Not run
A10: SD-07 | B10: Step 7 · Ask for more time | C10: The hours request goes to the manager | D10: High | E10: As EMP-DES-1, timer paused. | F10: 1. Hover the clock on the bar and press Request more time. 2. Ask for 1h 00m with a reason and send. 3. Sign in as MGR-DES and decide it. 4. Return as EMP-DES-1 and confirm. | G10: The request reaches MGR-DES as an HOURS decision, not a date change. Granting it raises the budget; the committed date only moves if the hours could not fit. The assignee confirms and the new figure is what the task runs on. | I10: Not run
A11: SD-08 | B11: Step 8 · Submit | C11: The work is handed in | D11: High | E11: As EMP-DES-1. | F11: 1. Note the deadline and the exact time now. 2. Submit with a note and one file. 3. Read the task status. | G11: Status becomes In review, the submission carries the note and file, and the assignee's action reads "Awaiting review". | I11: Not run
A12: SD-09 | B12: Step 9 · Rework | C12: It comes back with the leftover time | D12: High | E12: Signed in as MGR-DES. | F12: 1. Read the submission. 2. Send it back for rework with a note. 3. Note the moment you did. 4. Sign in as EMP-DES-1 and read the new deadline. | G12: The task returns to In progress and the new deadline is that moment plus the time that was left when it was submitted. | I12: Not run
A13: SD-10 | B13: Step 10 · Resubmit and approve | C13: The task closes | D13: High | E13: As EMP-DES-1, then MGR-DES. | F13: 1. Resubmit with a note. 2. As MGR-DES, approve. 3. Read the task, the list and the score ledger. | G13: The task is Completed. In the list it sits below all live work with a dash in the priority column. The score ledger records the completion and the earlier rework deduction once each. | I13: Not run
A14: SD-11 | B14: Step 11 · After | C14: Nothing is left claiming attention | D14: Medium | E14: After completion. | F14: 1. Read EMP-DES-1's bar on /home. 2. Read MGR-DES's My team. 3. Read the badges and counts. | G14: The completed task no longer occupies the bar (the next priority does, or the empty state shows). Badges and counts agree across the list, the board and the dashboard. | I14: Not run

Sheet E2E cross-dept
A1: E2E cross-dept — scripted run
A2: Run in order, top to bottom. MGR-DES → EMP-ENG-1 (FX-06), both gates through completion · 11 steps
A3: Test ID | B3: Area / step | C3: What is under test | D3: Priority | E3: Pre-condition | F3: Test steps | G3: Expected result | H3: Actual result | I3: Status | J3: Tested by | K3: Date | L3: Notes / defect ref
A4: XD-01 | B4: Step 1 · Create | C4: MGR-DES raises work for EMP-ENG-1 | D4: High | E4: Signed in as MGR-DES. Fixture FX-06. | F4: 1. /tasks/new → title "XD E2E — cross department", description, two requirements. 2. Assignee: EMP-ENG-1 (filter the picker by department = Engineering). 3. Read the relationship forecast. 4. Set a fixed due date and time and create. | G4: The forecast is the cross-department wording, the form offers a fixed DATE and no budget, and the created task's status is Pending approval for a cross-department reason. | I4: Not run
A5: XD-02 | B5: Step 2 · The assignee is told, not given | C5: Work is coming, but is not theirs | D5: High | E5: Signed in as EMP-ENG-1. | F5: 1. Open Notifications. 2. Open /home and read the bar. 3. Open My tasks. 4. Open the task by URL and try to act on it. | G5: A notification says work is heading their way pending approval — not that it has been assigned. The task is not owned work in their lists, and the page offers no accept, confirm or start control. | I5: Not run
